

<mujoco>





	<body name="baselink" pos="0 0 0">

		<joint armature="0.0001" axis="1 0 0" damping="1e+11" name="base:slide0" pos="0 0 0" type="slide"></joint>
		<joint armature="0.0001" axis="0 1 0" damping="1e+11" name="base:slide1" pos="0 0 0" type="slide"></joint>
		<joint armature="0.0001" axis="0 0 1" damping="1e+11" name="base:slide2" pos="0 0 0" type="slide"></joint>

		<inertial fullinertia="0.0247272 0.0491285 0.0472376 -8.0784E-05 0.00130902 -8.0419E-06" mass="6.21503193527" pos="-0.04204 8.01E-05 0.07964" ></inertial>

		<geom type="mesh" mesh="baselink" material="base_mat"></geom>

		<body name="link1" pos="0 0 0">

			<inertial fullinertia="0.0142175 0.0144041 0.0104533 -1.28579E-05 -2.31364E-05 1.93404E-05" mass="3.06736850696" pos="9.77E-05 -0.00012 0.23841" ></inertial>

			<geom type="mesh" mesh="link1" material="link1_mat" solimp="0.9 0.99 0.0001 0.01 6" solref="0.006 1" margin="0.001"></geom>

			<joint axis="0 0 1"  name="robot0:joint1" range="-2.87979 2.87979" type="hinge" limited="true"  armature="1" damping="50" frictionloss="0" stiffness="0"></joint>

			<body name="link2" pos="0 0 0.29">

				<inertial fullinertia="0.0603111 0.041569 0.0259548 9.83431E-06 5.72407E-05 -0.00050497" mass="3.90875060185" pos="0.00078 -0.00212 0.10124" ></inertial>

				<geom type="mesh" mesh="link2" material="link2_mat" solimp="0.9 0.99 0.0001 0.01 6" solref="0.006 1" margin="0.001"></geom>

				<joint axis="0 1 0"  name="robot0:joint2" range="-1.91986 1.91986" type="hinge" limited="true" armature="1" damping="50" frictionloss="0" stiffness="0" ></joint>
			
				
				<body name="link3" pos="0 0 0.27">

					<inertial fullinertia="0.00835606 0.016713 0.0126984 -8.01545E-05 0.00142884 -0.000182227" mass="2.94383262499" pos="0.02281 0.00106 0.05791" ></inertial>

					<geom type="mesh" mesh="link3" material="link3_mat" solimp="0.9 0.99 0.0001 0.01 6" solref="0.006 1" margin="0.001"></geom>

					<joint axis="0 1 0"  name="robot0:joint3" range="-1.91986 1.22173" type="hinge" limited="true" armature="1" damping="50" frictionloss="0" stiffness="0"></joint>


					<body name="link4" pos="0 0 0.07">

						<inertial fullinertia="0.00284661 0.00401346 0.0052535 -2.12765E-05 -1.6435E-05 1.31336E-05 " mass="1.32790527095" pos="0.2247 0.00015 0.00041" ></inertial>

						<geom type="mesh" mesh="link4"  material="link4_mat" solimp="0.9 0.99 0.0001 0.01 6" solref="0.006 1" margin="0.001"></geom>

						<joint axis="1 0 0"  name="robot0:joint4" range="-2.79253 2.79253" type="hinge" limited="true" armature="1" damping="50" frictionloss="0" stiffness="0"></joint>


						<body name="link5" pos="0.302 0 0">
					
							<inertial fullinertia="0.000404891 0.000892825 0.000815468 1.61943E-06 8.46805E-07 -1.51792E-08 " mass="0.546633236934" pos="-0.00109 3.68E-05 6.22E-05" ></inertial>

							<geom type="mesh" mesh="link5" material="link5_mat" solimp="0.9 0.99 0.0001 0.01 6" solref="0.006 1" margin="0.001"></geom>

							<joint axis="0 1 0"  name="robot0:joint5" range="-2.094395 2.094395" type="hinge" limited="true" armature="1" damping="50" frictionloss="0" stiffness="0"></joint>


							<body name="link6" pos="0.072 0 0">
					
								<inertial fullinertia=" 0.001 0.001 0.001 0 0 0 " mass="0.136784407912" pos="-0.00706 -0.00017 -1.32E-06" ></inertial>

								<geom type="mesh" mesh="link6" material="link6_mat" solimp="0.9 0.99 0.0001 0.01 6" solref="0.006 1" margin="0.001"></geom>
	
								<joint axis="1 0 0"  name="robot0:joint6" range="-6.98132 6.98132" type="hinge" limited="true" armature="1" damping="50" frictionloss="0" stiffness="0"></joint>

								<body name="tool" pos="0.09 0 0" >
									<inertial mass="0.5" pos="0 0 0 " ></inertial>
									<geom type="box" size="0.09 0.06 0.06" rgba="0.1 0.1 1 1" condim="1" solimp="0.9 0.99 0.0001 0.01 6" solref="0.006 1" margin="0.0001"> </geom>
									<site name="endeffector" pos="0.09 0 0" size="0.02" rgba="1 1 1 1" type="sphere"></site>
									<site name="force_sensor_site" pos="-0.090 0 0" size="0.04" rgba="1 1 1 1" type="sphere"></site>	

									<site name="torque_sensor_site" pos="-0.090 0 0" size="0.04" rgba="1 1 1 1" type="sphere"></site>	


								</body>
							</body>

						</body>
					</body>
				</body>
			</body>
		</body>
	</body>	

</mujoco>
